Workbook

Sheet Intro
A1: Input File for Pipe-Soil Interaction Analysis
A2: Instructions
A3: 1. Download code from GitHub
A4: 2. Save this file and code in the same location on your computer named PSI_Inputs
A5: 3. Populate 'Input' tab of this file
A6: 4. Open Python file 'PSI_montecarlo' and press run
A12: The following distribtuons are available for curve fitting:
A13: Uniform
A14: Normal
A15: Log-normal
A16: Weibull
A17: Gamma
... A20: Truncated Log-normal

Sheet Inputs
A1: Direct Inputs (No. Monte Carlo 'dice rolls' and Model Selection)
A2: No_rolls | B2: 10000 | H2: % number of sets of parameters to run PSI for, generally referred to as 'dice rolls'
A3: Emb_aslaid_model | B3: 0 | H3: % undrained: DNVGL-RP-F114 Model 1 = 0, DNVGL-RP-F114 Model 2/SAFEBUCK = 1, drained: DNVGL-RP-F114 = 10
A4: Emb_hydro_model | B4: 0 | H4: % as above
A5: Lat_brk_model | B5: 0 | C5: 2 | D5: 10 | H5: % undrained: DNVGL-RP-F114 Model 1 = 0, DNVGL-RP-F114 Model 2/SAFEBUCK = 1, Generalised FE Envelope = 2; drained: DNVGL-RP-F114 Model 1 = 10, DNVGL-RP-F114 Model 2/SAFEBUCK = 11
A6: Lat_brk_suction | B6: 0 | H6: % switch for suction at rear of pipe, not allowing = 0, allowing = 1 (relevant for lateral breakout undrained DNVGL-RP-F114 Model 1)
A7: Lat_brk_weighting | B7: 60 | C7: 80 | H7: % Min and Max weighting applied to Generalised FE Lat_brk result if used in conjunction with another Lat_brk Model; applied based on embedment and where accuracy of other models is expected to be lower (min weighting for envelope at z = 0; max at z ≥ 0.5D)
A8: Lat_res_model | B8: 0 | C8: 2 | D8: 10 | H8: % undrained: modified DNV = 0, DNVGL-RP-F114/SAFEBUCK = 1, Generalised FE Envelope = 2; drained: DNVGL-RP-F114 Model 1 = 10, DNVGL-RP-F114 Model 2/SAFEBUCK = 11
A9: Lat_res_suction | B9: 0 | H9: % switch for suction at rear of pipe, not allowing = 0, allowing = 1 (relevant for lateral residual undrained modified method)
A10: Lat_res_weighting | B10: 60 | C10: 80 | H10: % Min and Max weighting applied to Generalised FE Lat_res result if used in conjunction with another Lat_res Model; applied based on embedment and where accuracy of other models is expected to be lower (min weighting for envelope at z = 0; max at z ≥ 0.5D)
A11: Emb_res_model | B11: 2 | H11: % undrained: Embeding into Undisturbed Material DNVGL-RP-F114 Model 1 = 0, Embeding into Undisturbed Material DNVGL-RP-F114 Model 2/SAFEBUCK = 1, Horizontal Point on Generalised FE Envelope = 2; drained: Embeding into Undisturbed Material DNVGL-RP-F114 = 10
A12: Ax_model | B12: 0 | C12: 10 | H12: % undrained: SAFEBUCK with rate effects from DNVGL-RP-F114 = 0 (SAFEBUCK chosen over DNV as it directly uses interface strength profile rather than applying alpha factor for roughness and epsilon factor for partial remoulding, but otherwise calculation is the same), drained: DNVGL-RP-F114/SAFEBUCK = 10
A13: Cyc_model | B13: 2 | H13: % SAFEBUCK UD Lateral = 0 (not included in DNVGL-RP-F114, no axial option included); White & Cheuk 2008 = 1; Internal method transitioning from UD to D = 2
A14: No_cycles | B14: 1 | C14: 10 | D14: 100 | H14: % number of cycles to model for lateral cyclic resistance calculations
A15: N50 | B15: 4 | H15: % number of cycles for 50% transition between UD and D; Yan et al. 2014 examples approx. N50 = 2 (N95 = 5) and N50 = 4 (N95 = 18); more examples shown in excel 'Cyclic Curves from Yan 2014'
A16: su_profile | B16: 0 | H16: % soil-soil: only considering the top 1m, linear profile = 0, bi-linear profile = 1
A17: z_su_inv | B17: 0.5 | H17: % soil-soil: depth for inversion point for a bi-linear undrained shear strength profile (m) (can be left blank if linear profile selected)
A18: Output_dist | B18: Automated Fit | H18: % distribution for fitting output parameters (chosen from dropdown as for inputs excl. uniform distribution; normal distribution used where chosen fitting unsuccessful for a given parameter)
A19: Model_fct | B19: 1.2 | H19: % factor applied to all results to arbitrarily account for additional uncertainty by increaisng the bounds; applied linearly for each result where min/1.2 and max*1.2; MEAN WILL BE AFFECTED UNLESS IT IS HALF-WAY BETWEEN MIN AND MAX IN MAGNITUDE
A20: Berm | B20: 0 | H20: % switch to account for berm, not including = 0, including = 1
A21: Spanning | B21: 0 | H21: % switch to account for spanning, not including = 0, including = 1
A22: coeff_fenhance | B22: 0 | C22: 0 | D22: 1 | H22: % coefficients for second order polynomial fit for f,enhance to span ratio for passive component of DNV lateral breakout (D or UD formulations)
A23: TDZ_Wmultiplier | B23: 1 | H23: % multiplier on TDZ weight for FF calculations post-embedment calc; 1 for free-field
A25: Inputs Requiring Probabalistic Distribution Fitting (Pipe, Soil and Interface Parameters)
A26: Parameter | B26: LE (5%, or min when using Uniform distribution) | C26: BE (Mean) | D26: HE (95%, or max when using Uniform distribution) | E26: Min Value | F26: Max Value (only available for Truncated Log-normal) | G26: Distribution to Fit
A27: D | B27: 0.599 | C27: =B27 -> 0.599 | D27: =C27 -> 0.599 | G27: Uniform | H27: % pipe diameter (m)
A28: t | B28: =0.0214+0.04 -> 0.0614 | C28: =B28 -> 0.0614 | D28: =C28 -> 0.0614 | G28: Uniform | H28: % pipe wall thickness (m)
A29: W_empty | B29: 1.85 | C29: =B29 -> 1.85 | D29: =C29 -> 1.85 | G29: Uniform | H29: % submerged weight of empty pipe per unit length (kN/m)
A30: W_hydro | B30: 3.6 | C30: =B30 -> 3.6 | D30: =C30 -> 3.6 | G30: Uniform | H30: % submerged weight of flooded pipe during hydrotest per unit length (kN/m)
A31: W_op | B31: 3.06 | C31: =B31 -> 3.06 | D31: =C31 -> 3.06 | G31: Uniform | H31: % submerged weight of operating pipe per unit length (kN/m)
A32: alpha | B32: 0.5 | C32: 0.5 | D32: 0.5 | G32: Uniform | H32: % pipe-soil interface adhesion coefficient, fully smooth = 0 and fully rough = 1
A33: EI | B33: 233200 | C33: =B33 -> 233200 | D33: =C33 -> 233200 | G33: Uniform | H33: % pipe bending stiffness (kNm2)
A34: T0 | B34: 250 | C34: =B34 -> 250 | D34: =C34 -> 250 | G34: Uniform | H34: % bottom lay tension (kN)
A35: t_aslaid | B35: =7/12 -> 0.58333333 | C35: =(B35+D35)/2 -> 1.125 | D35: =20/12 -> 1.6666667 | G35: Uniform | H35: % time between pipe lay and hydrotest (years)
A36: t_hydro | B36: =1/12 -> 0.083333333 | C36: =(B36+D36)/2 -> 0.125 | D36: =2/12 -> 0.16666667 | G36: Uniform | H36: % time to complete hydrotest plus time pipe is left flooded between hydrotest and operation (years)
A37: t_preop | B37: =7/12 -> 0.58333333 | C37: =(B37+D37)/2 -> 1.2916667 | D37: =24/12 -> 2 | G37: Uniform | H37: % time pipe is left empty between hydrotest and operation (years)
A38: su_mudline | B38: 1.2 | C38: 6.3 | D38: 18.3 | E38: 0 | G38: Automated Fit | H38: % soil-soil: undrained shear strength at mudline (kPa)
A39: su_inv | B39: 0 | C39: 0 | D39: 0 | G39: Uniform | H39: % soil-soil: undrained shear strength at inversion point for a bi-linear profile, z_su_inv (kPa)
A40: delta_su | B40: 0.8 | C40: 3.1 | D40: 10.566667 | G40: Automated Fit | H40: % soil-soil: increase in undrained shear strength with depth (kPa/m), below inversion for a bi-linear profile
A41: gamma_sub | B41: 8.1 | C41: 8.1 | D41: 8.1 | G41: Uniform | H41: % submerged unit weight of soil (kN/m3)
...

Sheet Correlations
A1: Parameter | B1: Base Variable | C1: Correlation Type | D1: Correlation Index
A2: =Inputs!A27 -> D | D2: =IF(C2="Strongly Positive",0.9,IF(C2="Weakly Positive",0.6,IF(C2="Strongly Negative",-0.9,IF(C2="Weakly Negative",-0.6,""))))
A3: =Inputs!A28 -> t | D3: =IF(C3="Strongly Positive",0.9,IF(C3="Weakly Positive",0.6,IF(C3="Strongly Negative",-0.9,IF(C3="Weakly Negative",-0.6,""))))
A4: =Inputs!A29 -> W_empty | D4: =IF(C4="Strongly Positive",0.9,IF(C4="Weakly Positive",0.6,IF(C4="Strongly Negative",-0.9,IF(C4="Weakly Negative",-0.6,""))))
A5: =Inputs!A30 -> W_hydro | D5: =IF(C5="Strongly Positive",0.9,IF(C5="Weakly Positive",0.6,IF(C5="Strongly Negative",-0.9,IF(C5="Weakly Negative",-0.6,""))))
A6: =Inputs!A31 -> W_op | D6: =IF(C6="Strongly Positive",0.9,IF(C6="Weakly Positive",0.6,IF(C6="Strongly Negative",-0.9,IF(C6="Weakly Negative",-0.6,""))))
A7: =Inputs!A32 -> alpha | D7: =IF(C7="Strongly Positive",0.9,IF(C7="Weakly Positive",0.6,IF(C7="Strongly Negative",-0.9,IF(C7="Weakly Negative",-0.6,""))))
A8: =Inputs!A33 -> EI | D8: =IF(C8="Strongly Positive",0.9,IF(C8="Weakly Positive",0.6,IF(C8="Strongly Negative",-0.9,IF(C8="Weakly Negative",-0.6,""))))
A9: =Inputs!A34 -> T0 | D9: =IF(C9="Strongly Positive",0.9,IF(C9="Weakly Positive",0.6,IF(C9="Strongly Negative",-0.9,IF(C9="Weakly Negative",-0.6,""))))
A10: =Inputs!A35 -> t_aslaid | D10: =IF(C10="Strongly Positive",0.9,IF(C10="Weakly Positive",0.6,IF(C10="Strongly Negative",-0.9,IF(C10="Weakly Negative",-0.6,""))))
A11: =Inputs!A36 -> t_hydro | D11: =IF(C11="Strongly Positive",0.9,IF(C11="Weakly Positive",0.6,IF(C11="Strongly Negative",-0.9,IF(C11="Weakly Negative",-0.6,""))))
A12: =Inputs!A37 -> t_preop | D12: =IF(C12="Strongly Positive",0.9,IF(C12="Weakly Positive",0.6,IF(C12="Strongly Negative",-0.9,IF(C12="Weakly Negative",-0.6,""))))
A13: =Inputs!A38 -> su_mudline | D13: =IF(C13="Strongly Positive",0.9,IF(C13="Weakly Positive",0.6,IF(C13="Strongly Negative",-0.9,IF(C13="Weakly Negative",-0.6,""))))
A14: =Inputs!A39 -> su_inv | B14: su_mudline | C14: Strongly Positive | D14: =IF(C14="Strongly Positive",0.9,IF(C14="Weakly Positive",0.6,IF(C14="Strongly Negative",-0.9,IF(C14="Weakly Negative",-0.6,"")))) -> 0.9
A15: =Inputs!A40 -> delta_su | B15: su_mudline | C15: Strongly Positive | D15: =IF(C15="Strongly Positive",0.9,IF(C15="Weakly Positive",0.6,IF(C15="Strongly Negative",-0.9,IF(C15="Weakly Negative",-0.6,"")))) -> 0.9
A16: =Inputs!A41 -> gamma_sub
A17: =Inputs!A42 -> pipelay_St | B17: su_mudline | C17: Weakly Negative | D17: =IF(C17="Strongly Positive",0.9,IF(C17="Weakly Positive",0.6,IF(C17="Strongly Negative",-0.9,IF(C17="Weakly Negative",-0.6,"")))) -> -0.6
A18: =Inputs!A43 -> lateral_St | B18: su_mudline | C18: Weakly Negative | D18: =IF(C18="Strongly Positive",0.9,IF(C18="Weakly Positive",0.6,IF(C18="Strongly Negative",-0.9,IF(C18="Weakly Negative",-0.6,"")))) -> -0.6
A19: =Inputs!A44 -> cv | D19: =IF(C19="Strongly Positive",0.9,IF(C19="Weakly Positive",0.6,IF(C19="Strongly Negative",-0.9,IF(C19="Weakly Negative",-0.6,""))))
A20: =Inputs!A45 -> SHANSEP_S | B20: su_mudline | C20: Strongly Positive | D20: =IF(C20="Strongly Positive",0.9,IF(C20="Weakly Positive",0.6,IF(C20="Strongly Negative",-0.9,IF(C20="Weakly Negative",-0.6,"")))) -> 0.9
A21: =Inputs!A46 -> SHANSEP_m | B21: SHANSEP_S | C21: Strongly Positive | D21: =IF(C21="Strongly Positive",0.9,IF(C21="Weakly Positive",0.6,IF(C21="Strongly Negative",-0.9,IF(C21="Weakly Negative",-0.6,"")))) -> 0.9
A22: =Inputs!A47 -> ka | D22: =IF(C22="Strongly Positive",0.9,IF(C22="Weakly Positive",0.6,IF(C22="Strongly Negative",-0.9,IF(C22="Weakly Negative",-0.6,""))))
A23: =Inputs!A48 -> kp | D23: =IF(C23="Strongly Positive",0.9,IF(C23="Weakly Positive",0.6,IF(C23="Strongly Negative",-0.9,IF(C23="Weakly Negative",-0.6,""))))
A24: =Inputs!A49 -> phi | B24: su_mudline | C24: Strongly Positive | D24: =IF(C24="Strongly Positive",0.9,IF(C24="Weakly Positive",0.6,IF(C24="Strongly Negative",-0.9,IF(C24="Weakly Negative",-0.6,"")))) -> 0.9
A25: pipelay_Fct
A26: =Inputs!A51 -> int_SHANSEP_S | B26: SHANSEP_S | C26: Strongly Positive | D26: =IF(C26="Strongly Positive",0.9,IF(C26="Weakly Positive",0.6,IF(C26="Strongly Negative",-0.9,IF(C26="Weakly Negative",-0.6,"")))) -> 0.9
A27: =Inputs!A52 -> int_SHANSEP_m | B27: SHANSEP_m | C27: Strongly Positive | D27: =IF(C27="Strongly Positive",0.9,IF(C27="Weakly Positive",0.6,IF(C27="Strongly Negative",-0.9,IF(C27="Weakly Negative",-0.6,"")))) -> 0.9
A28: =Inputs!A53 -> delta | B28: phi | C28: Strongly Positive | D28: =IF(C28="Strongly Positive",0.9,IF(C28="Weakly Positive",0.6,IF(C28="Strongly Negative",-0.9,IF(C28="Weakly Negative",-0.6,"")))) -> 0.9
A29: eff_emb_ratio
A30: span_ratio
